<!DOCTYPE html>
<html lang="en">
  <head>
    <meta charset="UTF-8" />
    <meta http-equiv="X-UA-Compatible" content="IE=edge" />
    <meta name="viewport" content="width=device-width, initial-scale=1.0" />
    <title>Promise.retry()</title>
  </head>
  <body>
    <script>
      // English
      // -
      // succeed 成功 v
      // success 成功 n
      // successful 成功 adj
      // -
      // fail 失败 v
      // failure 失败n 失败的人n
      // failed 失败 adj / v过去式

      // Promise.retry 实现

      // 题目
      // 实现一个函数, fetchWithRetry 会自动重试3次，3次都失败则返回失败，任意一次成功直接返回成功时的数据

      // 注意
      // - 需要和 ( 本项目/2-FRONTEND/1-JS/FF-Promise.retry函数/Promise.retry.html ) 同步，因为随时在复习更新，可能会忘记同步两个一样的文件

      // ------- ------- ------- ------- ------- ------- -------
      // ------- ------- ------- ------- ------- ------- -------
      // 1
      // retry - promise版本
      Promise.retry_Promise = (fn, times) => {
        var errCount = 0;

        return new Promise((resolve, reject) => {
          // 注意: 这里之所以要包装一层 retry 函数，是因为fn执行失败后，还需要调fn，不能不能每次都写fn的then，catch；循环100遍的话显然手写链条不正确
          const retry = () => {
            fn()
              .then((res) => resolve(res)) // 成功，直接 resolve； 失败，递归执行count，直到times为0
              // .catch((err) => {
              //   if (times) {
              //     count();
              //     retry(); // 递归，失败后重新请求，直到重链次数为times后，还是失败则rejected，有一个成功则提前fulfilled
              //   }
              //   times--;
              //   // 失败times次后，reject
              //   // 同时也是改变了整个promise状态后，retry() 不会再次执行
              //   if (!times) {
              //     reject(err);
              //   }
              // });
              .catch((err) => {
                if (errCount === times) return reject(err);
                errCount++;
                console.log("failure");
                retry();
              });
          };

          retry();
        });
      };

      // ------- ------- ------- ------- ------- ------- -------
      // ------- ------- ------- ------- ------- ------- -------
      // 2
      // retry - async版本
      Promise.retry_AsyncAwait = (fetchFn, times) =>
        new Promise(async (resolve, reject) => {
          let errCount = 0;

          // 注意: 这里的 while 循环中有异步操作，并且是 await，所以每一次循环都会根据异步函数的时间来遍历，而不是很快遍历完
          while (times--) {
            try {
              const res = await fetchFn();
              return resolve(res); // 成功，不在catch说明请求成功
            } catch (err) {
              // 在 catch 中，说明 fetchFn 执行失败
              errCount++;
              console.log("failed times =>", errCount);

              // 失败到达 times 次后，reject
              if (!times) {
                return reject(err);
              }
            }
          }
        });

      // fetch
      // 1s响应，随机 fulfilled 或 reject
      const fetch = () => {
        return new Promise((resolve, reject) => {
          setTimeout(() => {
            return Math.random() - 0.9 > 0 ? resolve("success") : reject("failure");
          }, 1000);
        });
      };

      // test ->  Promise.retry_Promise
      Promise.retry_Promise(fetch, 3)
        .then((res) => console.log("Finally succeed:", res))
        .catch((err) => console.log("Finally fail:", err));

      // test ->  Promise.retry_AsyncAwait
      // Promise.retry_AsyncAwait(fetch, 3)
      //   .then((res) => console.log(res))
      //   .catch((err) => console.log(err));
    </script>
  </body>
</html>
